[2024-09-07T12:48:44.000+0000] {local_task_job_runner.py:120} INFO - ::group::Pre task execution logs
[2024-09-07T12:48:44.052+0000] {taskinstance.py:2073} INFO - Dependencies all met for dep_context=non-requeueable deps ti=<TaskInstance: reddit_etl.load_data_to_warehouse scheduled__2023-10-29T00:00:00+00:00 [queued]>
[2024-09-07T12:48:44.065+0000] {taskinstance.py:2073} INFO - Dependencies all met for dep_context=requeueable deps ti=<TaskInstance: reddit_etl.load_data_to_warehouse scheduled__2023-10-29T00:00:00+00:00 [queued]>
[2024-09-07T12:48:44.066+0000] {taskinstance.py:2303} INFO - Starting attempt 2 of 2
[2024-09-07T12:48:44.090+0000] {taskinstance.py:2327} INFO - Executing <Task(PythonOperator): load_data_to_warehouse> on 2023-10-29 00:00:00+00:00
[2024-09-07T12:48:44.101+0000] {logging_mixin.py:188} WARNING - /home/airflow/.local/lib/python3.12/site-packages/airflow/task/task_runner/standard_task_runner.py:61 DeprecationWarning: This process (pid=711) is multi-threaded, use of fork() may lead to deadlocks in the child.
[2024-09-07T12:48:44.103+0000] {standard_task_runner.py:63} INFO - Started process 714 to run task
[2024-09-07T12:48:44.101+0000] {standard_task_runner.py:90} INFO - Running: ['airflow', 'tasks', 'run', 'reddit_etl', 'load_data_to_warehouse', 'scheduled__2023-10-29T00:00:00+00:00', '--job-id', '130', '--raw', '--subdir', 'DAGS_FOLDER/reddit.py', '--cfg-path', '/tmp/tmpiv56rihq']
[2024-09-07T12:48:44.105+0000] {standard_task_runner.py:91} INFO - Job 130: Subtask load_data_to_warehouse
[2024-09-07T12:48:44.208+0000] {task_command.py:426} INFO - Running <TaskInstance: reddit_etl.load_data_to_warehouse scheduled__2023-10-29T00:00:00+00:00 [running]> on host 42d604ea5ce6
[2024-09-07T12:48:44.372+0000] {taskinstance.py:2644} INFO - Exporting env vars: AIRFLOW_CTX_DAG_OWNER='reddithackathon' AIRFLOW_CTX_DAG_ID='reddit_etl' AIRFLOW_CTX_TASK_ID='load_data_to_warehouse' AIRFLOW_CTX_EXECUTION_DATE='2023-10-29T00:00:00+00:00' AIRFLOW_CTX_TRY_NUMBER='2' AIRFLOW_CTX_DAG_RUN_ID='scheduled__2023-10-29T00:00:00+00:00'
[2024-09-07T12:48:44.374+0000] {taskinstance.py:430} INFO - ::endgroup::
[2024-09-07T12:48:44.438+0000] {logging_mixin.py:188} INFO - Error loading data: connection to server on socket "/var/run/postgresql/.s.PGSQL.5432" failed: No such file or directory
	Is the server running locally and accepting connections on that socket?
[2024-09-07T12:48:44.439+0000] {taskinstance.py:441} INFO - ::group::Post task execution logs
[2024-09-07T12:48:44.439+0000] {taskinstance.py:2890} ERROR - Task failed with exception
Traceback (most recent call last):
  File "/opt/airflow/dags/../scripts/load_data.py", line 28, in load_data
    connection = psycopg2.connect(
                 ^^^^^^^^^^^^^^^^^
  File "/home/airflow/.local/lib/python3.12/site-packages/psycopg2/__init__.py", line 122, in connect
    conn = _connect(dsn, connection_factory=connection_factory, **kwasync)
           ^^^^^^^^^^^^^^^^^^^^^^^^^^^^^^^^^^^^^^^^^^^^^^^^^^^^^^^^^^^^^^^
psycopg2.OperationalError: connection to server on socket "/var/run/postgresql/.s.PGSQL.5432" failed: No such file or directory
	Is the server running locally and accepting connections on that socket?


During handling of the above exception, another exception occurred:

Traceback (most recent call last):
  File "/opt/airflow/dags/../scripts/load_data.py", line 74, in load_data
    if connection:
       ^^^^^^^^^^
UnboundLocalError: cannot access local variable 'connection' where it is not associated with a value

During handling of the above exception, another exception occurred:

Traceback (most recent call last):
  File "/home/airflow/.local/lib/python3.12/site-packages/airflow/models/taskinstance.py", line 465, in _execute_task
    result = _execute_callable(context=context, **execute_callable_kwargs)
             ^^^^^^^^^^^^^^^^^^^^^^^^^^^^^^^^^^^^^^^^^^^^^^^^^^^^^^^^^^^^^
  File "/home/airflow/.local/lib/python3.12/site-packages/airflow/models/taskinstance.py", line 432, in _execute_callable
    return execute_callable(context=context, **execute_callable_kwargs)
           ^^^^^^^^^^^^^^^^^^^^^^^^^^^^^^^^^^^^^^^^^^^^^^^^^^^^^^^^^^^^
  File "/home/airflow/.local/lib/python3.12/site-packages/airflow/models/baseoperator.py", line 400, in wrapper
    return func(self, *args, **kwargs)
           ^^^^^^^^^^^^^^^^^^^^^^^^^^^
  File "/home/airflow/.local/lib/python3.12/site-packages/airflow/operators/python.py", line 235, in execute
    return_value = self.execute_callable()
                   ^^^^^^^^^^^^^^^^^^^^^^^
  File "/home/airflow/.local/lib/python3.12/site-packages/airflow/operators/python.py", line 252, in execute_callable
    return self.python_callable(*self.op_args, **self.op_kwargs)
           ^^^^^^^^^^^^^^^^^^^^^^^^^^^^^^^^^^^^^^^^^^^^^^^^^^^^^
  File "/opt/airflow/dags/reddit.py", line 53, in load_transformed_data
    load_data.load_data(post)  # Load each post using load_data script
    ^^^^^^^^^^^^^^^^^^^^^^^^^
  File "/opt/airflow/dags/../scripts/load_data.py", line 78, in load_data
    if cursor:
       ^^^^^^
UnboundLocalError: cannot access local variable 'cursor' where it is not associated with a value
[2024-09-07T12:48:44.463+0000] {taskinstance.py:1205} INFO - Marking task as FAILED. dag_id=reddit_etl, task_id=load_data_to_warehouse, execution_date=20231029T000000, start_date=20240907T124844, end_date=20240907T124844
[2024-09-07T12:48:44.488+0000] {standard_task_runner.py:110} ERROR - Failed to execute job 130 for task load_data_to_warehouse (cannot access local variable 'cursor' where it is not associated with a value; 714)
[2024-09-07T12:48:44.518+0000] {local_task_job_runner.py:240} INFO - Task exited with return code 1
[2024-09-07T12:48:44.564+0000] {taskinstance.py:3482} INFO - 0 downstream tasks scheduled from follow-on schedule check
[2024-09-07T12:48:44.566+0000] {local_task_job_runner.py:222} INFO - ::endgroup::
